Workbook
Name Utsnitt_Datum_formel: #N/A
Name Utsnitt_NUTS_3: #N/A
Name Utsnitt_Organisation_name: #N/A
Name Utsnitt_Programme: #N/A
Name Utsnitt_Project_name: #N/A
Name Utsnitt_Specific_objective: #N/A
Name Utsnitt_Type_of_partner: #N/A

Sheet Dashboard
B1: Interreg dashboard - Svenska partners | N1: =HYPERLINK("#Ordlista!A5","Ordlista") -> Ordlista
E3: Projekt | F3: (Alla) | I3: Organisation | J3: (Alla)
I10: =Top3Projekt!A1 -> Tre största projekten | J10: =Top3Projekt!B1 -> Summa Partnerbudget
I11: =IF(OR(Top3Projekt!A2="Totalsumma",Top3Projekt!A2=0),"-",Top3Projekt!A2) -> HALRIC - Hanseatic Life Science Research Infrastructure Consortium for triple-helix innovation | J11: =IF(I11="-","-",Top3Projekt!B2) -> 2096250
I12: =IF(OR(Top3Projekt!A3="Totalsumma",Top3Projekt!A3=0),"-",Top3Projekt!A3) -> SIRR | J12: =IF(I12="-","-",Top3Projekt!B3) -> 2077318
I13: =IF(OR(Top3Projekt!A4="Totalsumma",Top3Projekt!A4=0),"-",Top3Projekt!A4) -> DigiH4A | J13: =IF(I13="-","-",Top3Projekt!B4) -> 1631524
I14: Summa | J14: =SUM(J11:J13) -> 5805092
I16: =Top3Org!A1 -> Tre största organisationerna | J16: =Top3Org!B1 -> Summa Partnerbudget
I17: =IF(OR(Top3Org!A2="Totalsumma",Top3Org!A2=0),"-",Top3Org!A2) -> Luleå Tekniska Universitet | J17: =IF(I11="-","-",Top3Org!B2) -> 6775308.6
I18: =IF(OR(Top3Org!A3="Totalsumma",Top3Org!A3=0),"-",Top3Org!A3) -> Lunds Universitet | J18: =IF(I12="-","-",Top3Org!B3) -> 3656247
I19: =IF(OR(Top3Org!A4="Totalsumma",Top3Org!A4=0),"-",Top3Org!A4) -> Mittuniversitetet | J19: =IF(I13="-","-",Top3Org!B4) -> 2933275
E20: Summa ERDF: | F20: =GETPIVOTDATA("ERDF per partner",Budget!$A$3) -> 43327492 | I20: Summa | J20: =SUM(J17:J19) -> 13364831

Sheet Svenskt deltagande andel
B1: Svenskt deltagande
F3: Fyll enbart i siffrorna i denna kolumn
F4: ↓
E8: Programme / Type of partner | F8: Antal deltagande aktörer, totalt | G8: Antal deltagande aktörer, svenska | H8: Andel svenska projekt av totalt antal projekt, per program och typ av partner (%)
E9: AURORA | M9: Programme | N9: Type of partner | O9: =F8 -> Antal deltagande aktörer, totalt | P9: Antal deltagande aktörer, icke-svenska | Q9: =G8 -> Antal deltagande aktörer, svenska | R9: =H8 -> Andel svenska projekt av totalt antal projekt, per program och typ av partner (%)
E10: LP | F10: 98 | G10: {=_xlfn.LET( _xlpm.data, Rådata!A:Q, _xlpm.Programme, INDEX(_xlpm.data,,$G$49), _xlpm.TypeOfPartner, INDEX(_xlpm.data,,$G$58), _xlpm.ProjektNamn, INDEX(_xlpm.data,,$G$53), _xlpm.kriterier, ((_xlpm.Programme = E$9)*(_xlpm.TypeOfPartner=E10)), _xlpm.antal, SUM(_xlpm.kriterier), _xlpm.filtrerat, _xlfn._xlws.FILTER(_xlpm.ProjektNamn, _xlpm.kriterier), IF(_xlpm.antal=0, 0, COUNTA(_xlpm.filtrerat)) )} -> 41 | H10: =G10/F10 -> 0.41836735 | M10: =E9 -> AURORA | N10: =E10 -> LP | O10: =F10 -> 98 | P10: =O10-Q10 -> 57 | Q10: =G10 -> 41 | R10: =H10 -> 0.41836735
E11: PP | F11: 298 | G11: {=_xlfn.LET( _xlpm.data, Rådata!A:Q, _xlpm.Programme, INDEX(_xlpm.data,,$G$49), _xlpm.TypeOfPartner, INDEX(_xlpm.data,,$G$58), _xlpm.ProjektNamn, INDEX(_xlpm.data,,$G$53), _xlpm.kriterier, ((_xlpm.Programme = E$9)*(_xlpm.TypeOfPartner=E11)), _xlpm.antal, SUM(_xlpm.kriterier), _xlpm.filtrerat, _xlfn._xlws.FILTER(_xlpm.ProjektNamn, _xlpm.kriterier), IF(_xlpm.antal=0, 0, COUNTA(_xlpm.filtrerat)) )} -> 172 | H11: =G11/F11 -> 0.57718121 | N11: =E11 -> PP | O11: =F11 -> 298 | P11: =O11-Q11 -> 126 | Q11: =G11 -> 172 | R11: =H11 -> 0.57718121
E12: Baltic Sea Region
E13: LP | F13: 107 | G13: {=_xlfn.LET( _xlpm.data, Rådata!A:Q, _xlpm.Programme, INDEX(_xlpm.data,,$G$49), _xlpm.TypeOfPartner, INDEX(_xlpm.data,,$G$58), _xlpm.ProjektNamn, INDEX(_xlpm.data,,$G$53), _xlpm.kriterier, ((_xlpm.Programme = E$12)*(_xlpm.TypeOfPartner=E13)), _xlpm.antal, SUM(_xlpm.kriterier), _xlpm.filtrerat, _xlfn._xlws.FILTER(_xlpm.ProjektNamn, _xlpm.kriterier), IF(_xlpm.antal=0, 0, COUNTA(_xlpm.filtrerat)) )} -> 14 | H13: =G13/F13 -> 0.13084112 | M13: =E12 -> Baltic Sea Region | N13: =E13 -> LP | O13: =F13 -> 107 | P13: =O13-Q13 -> 93 | Q13: =G13 -> 14 | R13: =H13 -> 0.13084112
E14: PP | F14: 1122 | G14: {=_xlfn.LET( _xlpm.data, Rådata!A:Q, _xlpm.Programme, INDEX(_xlpm.data,,$G$49), _xlpm.TypeOfPartner, INDEX(_xlpm.data,,$G$58), _xlpm.ProjektNamn, INDEX(_xlpm.data,,$G$53), _xlpm.kriterier, ((_xlpm.Programme = E$12)*(_xlpm.TypeOfPartner=E14)), _xlpm.antal, SUM(_xlpm.kriterier), _xlpm.filtrerat, _xlfn._xlws.FILTER(_xlpm.ProjektNamn, _xlpm.kriterier), IF(_xlpm.antal=0, 0, COUNTA(_xlpm.filtrerat)) )} -> 148 | H14: =G14/F14 -> 0.13190731 | N14: =E14 -> PP | O14: =F14 -> 1122 | P14: =O14-Q14 -> 974 | Q14: =G14 -> 148 | R14: =H14 -> 0.13190731
E15: Central Baltic
E16: LP | F16: 63 | G16: {=_xlfn.LET( _xlpm.data, Rådata!A:Q, _xlpm.Programme, INDEX(_xlpm.data,,$G$49), _xlpm.TypeOfPartner, INDEX(_xlpm.data,,$G$58), _xlpm.ProjektNamn, INDEX(_xlpm.data,,$G$53), _xlpm.kriterier, ((_xlpm.Programme = E$15)*(_xlpm.TypeOfPartner=E16)), _xlpm.antal, SUM(_xlpm.kriterier), _xlpm.filtrerat, _xlfn._xlws.FILTER(_xlpm.ProjektNamn, _xlpm.kriterier), IF(_xlpm.antal=0, 0, COUNTA(_xlpm.filtrerat)) )} -> 8 | H16: =G16/F16 -> 0.12698413 | M16: =E15 -> Central Baltic | N16: =E16 -> LP | O16: =F16 -> 63 | P16: =O16-Q16 -> 55 | Q16: =G16 -> 8 | R16: =H16 -> 0.12698413
E17: PP | F17: 185 | G17: {=_xlfn.LET( _xlpm.data, Rådata!A:Q, _xlpm.Programme, INDEX(_xlpm.data,,$G$49), _xlpm.TypeOfPartner, INDEX(_xlpm.data,,$G$58), _xlpm.ProjektNamn, INDEX(_xlpm.data,,$G$53), _xlpm.kriterier, ((_xlpm.Programme = E$15)*(_xlpm.TypeOfPartner=E17)), _xlpm.antal, SUM(_xlpm.kriterier), _xlpm.filtrerat, _xlfn._xlws.FILTER(_xlpm.ProjektNamn, _xlpm.kriterier), IF(_xlpm.antal=0, 0, COUNTA(_xlpm.filtrerat)) )} -> 53 | H17: =G17/F17 -> 0.28648649 | N17: =E17 -> PP | O17: =F17 -> 185 | P17: =O17-Q17 -> 132 | Q17: =G17 -> 53 | R17: =H17 -> 0.28648649
E18: Interreg europe
E19: LP | F19: 263 | G19: {=_xlfn.LET( _xlpm.data, Rådata!A:Q, _xlpm.Programme, INDEX(_xlpm.data,,$G$49), _xlpm.TypeOfPartner, INDEX(_xlpm.data,,$G$58), _xlpm.ProjektNamn, INDEX(_xlpm.data,,$G$53), _xlpm.kriterier, ((_xlpm.Programme = E$18)*(_xlpm.TypeOfPartner=E19)), _xlpm.antal, SUM(_xlpm.kriterier), _xlpm.filtrerat, _xlfn._xlws.FILTER(_xlpm.ProjektNamn, _xlpm.kriterier), IF(_xlpm.antal=0, 0, COUNTA(_xlpm.filtrerat)) )} -> 7 | H19: =G19/F19 -> 0.02661597 | M19: =E18 -> Interreg europe | N19: =E19 -> LP | O19: =F19 -> 263 | P19: =O19-Q19 -> 256 | Q19: =G19 -> 7 | R19: =H19 -> 0.02661597
E20: PP | F20: 1874 | G20: {=_xlfn.LET( _xlpm.data, Rådata!A:Q, _xlpm.Programme, INDEX(_xlpm.data,,$G$49), _xlpm.TypeOfPartner, INDEX(_xlpm.data,,$G$58), _xlpm.ProjektNamn, INDEX(_xlpm.data,,$G$53), _xlpm.kriterier, ((_xlpm.Programme = E$18)*(_xlpm.TypeOfPartner=E20)), _xlpm.antal, SUM(_xlpm.kriterier), _xlpm.filtrerat, _xlfn._xlws.FILTER(_xlpm.ProjektNamn, _xlpm.kriterier), IF(_xlpm.antal=0, 0, COUNTA(_xlpm.filtrerat)) )} -> 58 | H20: =G20/F20 -> 0.03094984 | N20: =E20 -> PP | O20: =F20 -> 1874 | P20: =O20-Q20 -> 1816 | Q20: =G20 -> 58 | R20: =H20 -> 0.03094984
E21: Interreg North Sea
E22: LP | F22: 65 | G22: {=_xlfn.LET( _xlpm.data, Rådata!A:Q, _xlpm.Programme, INDEX(_xlpm.data,,$G$49), _xlpm.TypeOfPartner, INDEX(_xlpm.data,,$G$58), _xlpm.ProjektNamn, INDEX(_xlpm.data,,$G$53), _xlpm.kriterier, ((_xlpm.Programme = E$21)*(_xlpm.TypeOfPartner=E22)), _xlpm.antal, SUM(_xlpm.kriterier), _xlpm.filtrerat, _xlfn._xlws.FILTER(_xlpm.ProjektNamn, _xlpm.kriterier), IF(_xlpm.antal=0, 0, COUNTA(_xlpm.filtrerat)) )} -> 7 | H22: =G22/F22 -> 0.10769231 | M22: =E21 -> Interreg North Sea | N22: =E22 -> LP | O22: =F22 -> 65 | P22: =O22-Q22 -> 58 | Q22: =G22 -> 7 | R22: =H22 -> 0.10769231
E23: PP | F23: 791 | G23: {=_xlfn.LET( _xlpm.data, Rådata!A:Q, _xlpm.Programme, INDEX(_xlpm.data,,$G$49), _xlpm.TypeOfPartner, INDEX(_xlpm.data,,$G$58), _xlpm.ProjektNamn, INDEX(_xlpm.data,,$G$53), _xlpm.kriterier, ((_xlpm.Programme = E$21)*(_xlpm.TypeOfPartner=E23)), _xlpm.antal, SUM(_xlpm.kriterier), _xlpm.filtrerat, _xlfn._xlws.FILTER(_xlpm.ProjektNamn, _xlpm.kriterier), IF(_xlpm.antal=0, 0, COUNTA(_xlpm.filtrerat)) )} -> 78 | H23: =G23/F23 -> 0.098609355 | N23: =E23 -> PP | O23: =F23 -> 791 | P23: =O23-Q23 -> 713 | Q23: =G23 -> 78 | R23: =H23 -> 0.098609355
E24: Northern Periphery and Arctic
E25: LP | F25: 43 | G25: {=_xlfn.LET( _xlpm.data, Rådata!A:Q, _xlpm.Programme, INDEX(_xlpm.data,,$G$49), _xlpm.TypeOfPartner, INDEX(_xlpm.data,,$G$58), _xlpm.ProjektNamn, INDEX(_xlpm.data,,$G$53), _xlpm.kriterier, ((_xlpm.Programme = E$24)*(_xlpm.TypeOfPartner=E25)), _xlpm.antal, SUM(_xlpm.kriterier), _xlpm.filtrerat, _xlfn._xlws.FILTER(_xlpm.ProjektNamn, _xlpm.kriterier), IF(_xlpm.antal=0, 0, COUNTA(_xlpm.filtrerat)) )} -> 7 | H25: =G25/F25 -> 0.1627907 | M25: =E24 -> Northern Periphery and Arctic | N25: =E25 -> LP | O25: =F25 -> 43 | P25: =O25-Q25 -> 36 | Q25: =G25 -> 7 | R25: =H25 -> 0.1627907
E26: PP | F26: 202 | G26: {=_xlfn.LET( _xlpm.data, Rådata!A:Q, _xlpm.Programme, INDEX(_xlpm.data,,$G$49), _xlpm.TypeOfPartner, INDEX(_xlpm.data,,$G$58), _xlpm.ProjektNamn, INDEX(_xlpm.data,,$G$53), _xlpm.kriterier, ((_xlpm.Programme = E$24)*(_xlpm.TypeOfPartner=E26)), _xlpm.antal, SUM(_xlpm.kriterier), _xlpm.filtrerat, _xlfn._xlws.FILTER(_xlpm.ProjektNamn, _xlpm.kriterier), IF(_xlpm.antal=0, 0, COUNTA(_xlpm.filtrerat)) )} -> 40 | H26: =G26/F26 -> 0.1980198 | N26: =E26 -> PP | O26: =F26 -> 202 | P26: =O26-Q26 -> 162 | Q26: =G26 -> 40 | R26: =H26 -> 0.1980198
E27: South Baltic Programme
E28: LP | F28: 40 | G28: {=_xlfn.LET( _xlpm.data, Rådata!A:Q, _xlpm.Programme, INDEX(_xlpm.data,,$G$49), _xlpm.TypeOfPartner, INDEX(_xlpm.data,,$G$58), _xlpm.ProjektNamn, INDEX(_xlpm.data,,$G$53), _xlpm.kriterier, ((_xlpm.Programme = E$27)*(_xlpm.TypeOfPartner=E28)), _xlpm.antal, SUM(_xlpm.kriterier), _xlpm.filtrerat, _xlfn._xlws.FILTER(_xlpm.ProjektNamn, _xlpm.kriterier), IF(_xlpm.antal=0, 0, COUNTA(_xlpm.filtrerat)) )} -> 8 | H28: =G28/F28 -> 0.2 | M28: =E27 -> South Baltic Programme | N28: =E28 -> LP | O28: =F28 -> 40 | P28: =O28-Q28 -> 32 | Q28: =G28 -> 8 | R28: =H28 -> 0.2
E29: PP | F29: 284 | G29: {=_xlfn.LET( _xlpm.data, Rådata!A:Q, _xlpm.Programme, INDEX(_xlpm.data,,$G$49), _xlpm.TypeOfPartner, INDEX(_xlpm.data,,$G$58), _xlpm.ProjektNamn, INDEX(_xlpm.data,,$G$53), _xlpm.kriterier, ((_xlpm.Programme = E$27)*(_xlpm.TypeOfPartner=E29)), _xlpm.antal, SUM(_xlpm.kriterier), _xlpm.filtrerat, _xlfn._xlws.FILTER(_xlpm.ProjektNamn, _xlpm.kriterier), IF(_xlpm.antal=0, 0, COUNTA(_xlpm.filtrerat)) )} -> 59 | H29: =G29/F29 -> 0.20774648 | N29: =E29 -> PP | O29: =F29 -> 284 | P29: =O29-Q29 -> 225 | Q29: =G29 -> 59 | R29: =H29 -> 0.20774648
E30: Sverige-Norge
E31: LP | F31: 60 | G31: {=_xlfn.LET( _xlpm.data, Rådata!A:Q, _xlpm.Programme, INDEX(_xlpm.data,,$G$49), _xlpm.TypeOfPartner, INDEX(_xlpm.data,,$G$58), _xlpm.ProjektNamn, INDEX(_xlpm.data,,$G$53), _xlpm.kriterier, ((_xlpm.Programme = E$30)*(_xlpm.TypeOfPartner=E31)), _xlpm.antal, SUM(_xlpm.kriterier), _xlpm.filtrerat, _xlfn._xlws.FILTER(_xlpm.ProjektNamn, _xlpm.kriterier), IF(_xlpm.antal=0, 0, COUNTA(_xlpm.filtrerat)) )} -> 68 | H31: =G31/F31 -> 1.1333333 | M31: =E30 -> Sverige-Norge | N31: =E31 -> LP | O31: =F31 -> 60 | P31: =O31-Q31 -> -8 | Q31: =G31 -> 68 | R31: =H31 -> 1.1333333
E32: PP | F32: 152 | G32: {=_xlfn.LET( _xlpm.data, Rådata!A:Q, _xlpm.Programme, INDEX(_xlpm.data,,$G$49), _xlpm.TypeOfPartner, INDEX(_xlpm.data,,$G$58), _xlpm.ProjektNamn, INDEX(_xlpm.data,,$G$53), _xlpm.kriterier, ((_xlpm.Programme = E$30)*(_xlpm.TypeOfPartner=E32)), _xlpm.antal, SUM(_xlpm.kriterier), _xlpm.filtrerat, _xlfn._xlws.FILTER(_xlpm.ProjektNamn, _xlpm.kriterier), IF(_xlpm.antal=0, 0, COUNTA(_xlpm.filtrerat)) )} -> 49 | H32: =G32/F32 -> 0.32236842 | N32: =E32 -> PP | O32: =F32 -> 152 | P32: =O32-Q32 -> 103 | Q32: =G32 -> 49 | R32: =H32 -> 0.32236842
E33: URBACT IV
E34: LP | F34: 45 | G34: {=_xlfn.LET( _xlpm.data, Rådata!A:Q, _xlpm.Programme, INDEX(_xlpm.data,,$G$49), _xlpm.TypeOfPartner, INDEX(_xlpm.data,,$G$58), _xlpm.ProjektNamn, INDEX(_xlpm.data,,$G$53), _xlpm.kriterier, ((_xlpm.Programme = E$33)*(_xlpm.TypeOfPartner=E34)), _xlpm.antal, SUM(_xlpm.kriterier), _xlpm.filtrerat, _xlfn._xlws.FILTER(_xlpm.ProjektNamn, _xlpm.kriterier), IF(_xlpm.antal=0, 0, COUNTA(_xlpm.filtrerat)) )} -> 0 | H34: =G34/F34 -> 0 | M34: =E33 -> URBACT IV | N34: =E34 -> LP | O34: =F34 -> 45 | P34: =O34-Q34 -> 45 | Q34: =G34 -> 0 | R34: =H34 -> 0
E35: PP | F35: 345 | G35: {=_xlfn.LET( _xlpm.data, Rådata!A:Q, _xlpm.Programme, INDEX(_xlpm.data,,$G$49), _xlpm.TypeOfPartner, INDEX(_xlpm.data,,$G$58), _xlpm.ProjektNamn, INDEX(_xlpm.data,,$G$53), _xlpm.kriterier, ((_xlpm.Programme = E$33)*(_xlpm.TypeOfPartner=E35)), _xlpm.antal, SUM(_xlpm.kriterier), _xlpm.filtrerat, _xlfn._xlws.FILTER(_xlpm.ProjektNamn, _xlpm.kriterier), IF(_xlpm.antal=0, 0, COUNTA(_xlpm.filtrerat)) )} -> 5 | H35: =G35/F35 -> 0.014492754 | N35: =E35 -> PP | O35: =F35 -> 345 | P35: =O35-Q35 -> 340 | Q35: =G35 -> 5 | R35: =H35 -> 0.014492754
E36: Öresund-Kattegat-Skagerrak
E37: LP | F37: 64 | G37: {=_xlfn.LET( _xlpm.data, Rådata!A:Q, _xlpm.Programme, INDEX(_xlpm.data,,$G$49), _xlpm.TypeOfPartner, INDEX(_xlpm.data,,$G$58), _xlpm.ProjektNamn, INDEX(_xlpm.data,,$G$53), _xlpm.kriterier, ((_xlpm.Programme = E$36)*(_xlpm.TypeOfPartner=E37)), _xlpm.antal, SUM(_xlpm.kriterier), _xlpm.filtrerat, _xlfn._xlws.FILTER(_xlpm.ProjektNamn, _xlpm.kriterier), IF(_xlpm.antal=0, 0, COUNTA(_xlpm.filtrerat)) )} -> 28 | H37: =G37/F37 -> 0.4375 | M37: =E36 -> Öresund-Kattegat-Skagerrak | N37: =E37 -> LP | O37: =F37 -> 64 | P37: =O37-Q37 -> 36 | Q37: =G37 -> 28 | R37: =H37 -> 0.4375
E38: PP | F38: 471 | G38: {=_xlfn.LET( _xlpm.data, Rådata!A:Q, _xlpm.Programme, INDEX(_xlpm.data,,$G$49), _xlpm.TypeOfPartner, INDEX(_xlpm.data,,$G$58), _xlpm.ProjektNamn, INDEX(_xlpm.data,,$G$53), _xlpm.kriterier, ((_xlpm.Programme = E$36)*(_xlpm.TypeOfPartner=E38)), _xlpm.antal, SUM(_xlpm.kriterier), _xlpm.filtrerat, _xlfn._xlws.FILTER(_xlpm.ProjektNamn, _xlpm.kriterier), IF(_xlpm.antal=0, 0, COUNTA(_xlpm.filtrerat)) )} -> 176 | H38: =G38/F38 -> 0.37367304 | N38: =E38 -> PP | O38: =F38 -> 471 | P38: =O38-Q38 -> 295 | Q38: =G38 -> 176 | R38: =H38 -> 0.37367304
F45: Notera vilken kolumn som formeln ska titta i för att räkna antal unika värden
F46: Rådata: Tabell1
F47: KolNamn | G47: KolNummer
F48: # | G48: 1
F49: Programme | G49: 2
F50: Type of project | G50: 3
...

Sheet Tabell med projekt
A1: Programme | B1: Policy objective | C1: Specific objective | D1: Type of project | E1: Project name | F1: Organisation name | G1: Organisation ownership | H1: Type of organisation | I1: Type of partner | J1: NUTS 3 | K1: Summa av ERDF per partner
A2: Baltic Sea Region | B2: PO1 | C2: RSO1.1 | D2: Regular | E2: Arts on Prescription | F2: Sunderby folkhögskola | G2: Public | H2: Education and research institution | I2: PP | J2: Norrbottens län | K2: 196588.21
A3: Baltic Sea Region | B3: PO1 | C3: RSO1.1 | D3: Regular | E3: Arts on Prescription | F3: Region Norrbotten | G3: Public | H3: Regional public authority | I3: PP | J3: Norrbottens län | K3: 223552
A4: Baltic Sea Region | B4: PO1 | C4: RSO1.1 | D4: Regular | E4: Arts on Prescription | F4: NDPHS | G4: Public | H4: International governmental organisation | I4: PP | J4: Stockholms län | K4: 304039.98
A5: Baltic Sea Region | B5: PO1 | C5: RSO1.1 | D5: Regular | E5: RESIST | F5: Region Västerbotten | G5: Public | H5: Regional public authority | I5: PP | J5: Västerbottens län | K5: 351912
A6: Baltic Sea Region | B6: PO1 | C6: RSO1.1 | D6: Regular | E6: RESIST | F6: Malmö Universitet | G6: Public | H6: Higher education and research institution | I6: PP | J6: Skåne län | K6: 233283.6
A7: Baltic Sea Region | B7: PO1 | C7: RSO1.1 | D7: Regular | E7: SmartAging | F7: Interesting Times Gang AB | G7: Private | H7: Small or medium-sized enterprise (SME) | I7: PP | J7: Stockholms län | K7: 109200
A8: Baltic Sea Region | B8: PO1 | C8: RSO1.1 | D8: Regular | E8: CliNeDest | F8: Kungliga Djurgårdens Intressenter AB | G8: Private | H8: Business support organisation | I8: PP | J8: Stockholms län | K8: 284003.28
A9: Baltic Sea Region | B9: PO1 | C9: RSO1.1 | D9: Regular | E9: REDIRECT | F9: Lunds Kommun | G9: Public | H9: Local public authority | I9: PP | J9: Skåne län | K9: 225092.8
A10: Baltic Sea Region | B10: PO1 | C10: RSO1.1 | D10: Regular | E10: CREWS | F10: CBSS | G10: Public | H10: International governmental organisation | I10: PP | J10: Stockholms län | K10: 277568.48
A11: Baltic Sea Region | B11: PO1 | C11: RSO1.1 | D11: Regular | E11: DIVERSE_GENE_WATCH | F11: #SAKNAS! | K11: 151030.3
A12: Baltic Sea Region | B12: PO1 | C12: RSO1.1 | D12: Small | E12: Mobile Hospital | F12: Karolinska Universitetssjukhuset | G12: Public | H12: Regional public authority | I12: PP | J12: Stockholms län | K12: 97198.08
A13: Baltic Sea Region | B13: PO1 | C13: RSO1.1 | D13: Small | E13: StratKIT+ | F13: Södertälje kommun | G13: Public | H13: Local public authority | I13: PP | J13: Stockholms län | K13: 35106.48
A14: Baltic Sea Region | B14: PO1 | C14: RSO1.1 | D14: Small | E14: StratKIT+ | F14: Göteborgs Universitet | G14: Public | H14: Higher education and research institution | I14: PP | J14: Västra Götalands län | K14: 28876.91
A15: Interreg europe | B15: PO1 | C15: RSO1.1 | D15: Regular | E15: DeepTechValleys | F15: Region Västerbotten | G15: Public | H15: Regional public authority | I15: PP | J15: Västerbottens län | K15: 206080
A16: Interreg europe | B16: PO1 | C16: RSO1.1 | D16: Regular | E16: HERCULES | F16: Region Västerbotten | G16: Public | H16: Regional public authority | I16: PP | J16: Västerbottens län | K16: 180976
A17: AURORA | B17: PO1 | C17: RSO1.1 | D17: Regular | E17: GreenBattery | F17: SLU | G17: Public | H17: Higher education and research institution | I17: PP | J17: Västerbottens län | K17: 162314
A18: AURORA | B18: PO1 | C18: RSO1.1 | D18: Regular | E18: GreenBattery | F18: Rise Processum AB | G18: Public | H18: Higher education and research institution | I18: LP | J18: Västernorrlands län | K18: 162475
A19: AURORA | B19: PO1 | C19: RSO1.1 | D19: Regular | E19: SUSEN - Knowledge and networking platform for sustainable electronics based on northern bioresources - Sustainable electronics from Northern bioresources - Biotronics | F19: Luleå Tekniska Universitet | G19: Public | H19: Higher education and research institution | I19: PP | J19: Norrbottens län | K19: 285058
A20: AURORA | B20: PO1 | C20: RSO1.1 | D20: Regular | E20: Arctic 6G | F20: Luleå Tekniska Universitet | G20: Public | H20: Higher education and research institution | I20: LP | J20: Norrbottens län | K20: 648941
A21: AURORA | B21: PO1 | C21: RSO1.1 | D21: Regular | E21: HE4T - Harvesting Energy for Data Acquisition and Transfer | F21: Luleå Tekniska Universitet | G21: Public | H21: Higher education and research institution | I21: PP | J21: Norrbottens län | K21: 388085
A22: AURORA | B22: PO1 | C22: RSO1.1 | D22: Regular | E22: Summation - (Sustainable Autonomous Systems and Solutions) | F22: Luleå Tekniska Universitet | G22: Public | H22: Higher education and research institution | I22: PP | J22: Norrbottens län | K22: 200000
A23: AURORA | B23: PO1 | C23: RSO1.1 | D23: Regular | E23: Eco-friendly and sustainable method for recycling of spent lithium-ion batteries (EcoLIB) | F23: Luleå Tekniska Universitet | G23: Public | H23: Higher education and research institution | I23: PP | J23: Norrbottens län | K23: 225257
... A172: Interreg North Sea | B172: PO1 | C172: RSO1.1 | D172: Full Application | E172: H2ignite | F172: Lindholmen Science Park AB | G172: Public | H172: Higher education and research institution | I172: PP | J172: Västra Götalands län | K172: 215858

Sheet Ordlista
B1: Specifikt mål | C1: Definition
B2: RSO1.1 | C2: Stärka forskning och innovation
B3: RSO1.2 | C3: Säkra nyttan av digitaliseringen
B4: RSO1.3 | C4: Små och medelstora företags tillväxt och konkurrenskraft
B5: RSO1.4 | C5: Kompetens för smart specialisering och omställning
B6: RSO1.5 | C6: Digital konnektivitet
B7: RSO2.1 | C7: Energieffektivitet
B8: RSO2.2 | C8: Förnybar energi
B9: RSO2.3 | C9: Smarta energisystem
B10: RSO2.4 | C10: Anpassa till klimatförändringarna
B11: RSO2.5 | C11: Främjande av tillgång till vatten och hållbar vattenförvaltning
B12: RSO2.6 | C12: Cirkulär ekonomi
... B23: JSO8.1 | C23: Fonden för rättvis omställning

Sheet Rådata
A1: Please note that you are only supposed to enter projects and organisations approved in Sweden
A2: Obs | B2: Name of the programme | C2: Regular, Small, or Feasibility study [i.e., "förstudie"] | D2: Date format: yyyy-mm-dd | E2: Date format: yyyy-mm-dd | F2: Abbrevation of the project name | G2: VAT format: xx-xxxxxxxxxxxx | H2: Original name in Swedish | I2: Privately of publicly majority owned organisation | J2: << Lägg in förklaring >> | K2: Lead partner (LP), Project partner (PP), or Associate partner (AP) | L2: City of registered organisation | M2: Regional classification (NUTS 3) | N2: Regional classification (NUTS 2) | O2: Granted EU funding per partner (in euro) | P2: Policy objective (numeric code) | Q2: Specific objective (numeric code) | R2: Formel för datum | S2: Karthjälp
A3: # | B3: Programme | C3: Type of project | D3: Start date | E3: End date | F3: Project name | G3: VAT number | H3: Organisation name | I3: Organisation ownership | J3: Type of organisation | K3: Type of partner | L3: Kolumn1 | M3: NUTS 3 | N3: NUTS 2 | O3: ERDF per partner | P3: Policy objective | Q3: Specific objective | R3: Datum_formel | S3: Land
A4: 23 | B4: AURORA | C4: Regular | D4: 44927 | E4: 46022 | F4: Boost Nordic Biogas | G4: SE556664159201 | H4: BioFuel Region BFR AB | I4: Public | J4: Regional public authority | K4: PP | L4: Umeå | M4: Västerbottens län | N4: Övre Norrland | O4: 149355 | P4: PO1 | Q4: RSO1.1 | R4: =IF(D4="0. Inget datum inlagt",Tabell1[[#This Row],[Start date]],YEAR(D4)) -> 2023 | S4: Sverige
A5: 51 | B5: AURORA | C5: Regular | D5: 45170 | E5: 46265 | F5: Nature refines | G5: SE556664159201 | H5: BioFuel Region BFR AB | I5: Public | J5: Regional public authority | K5: PP | L5: Umeå | M5: Västerbottens län | N5: Övre Norrland | O5: 51870 | P5: PO1 | Q5: RSO1.1 | R5: =IF(D5="0. Inget datum inlagt",Tabell1[[#This Row],[Start date]],YEAR(D5)) -> 2023 | S5: Sverige
A6: 92 | B6: AURORA | C6: Regular | D6: 45292 | E6: 46387 | F6: X Border Support4Games (Support structure for Game Start ups in the Arctic) | G6: SE556958669501 | H6: Creative Crowd AB | I6: Private | J6: Small or medium-sized enterprise (SME) | K6: PP | L6: Skellefteå | M6: Västerbottens län | N6: Övre Norrland | O6: 350352 | P6: PO1 | Q6: RSO1.3 | R6: =IF(D6="0. Inget datum inlagt",Tabell1[[#This Row],[Start date]],YEAR(D6)) -> 2024 | S6: Sverige
A7: 66 | B7: AURORA | C7: Regular | D7: 45200 | E7: 46295 | F7: Best practices for sustainable stabilisation and reuse of sulfidic soils with minimised environmental impact (MinImpact) | G7: SE556911133801 | H7: Dåva deponi och avfallscenter i Umeå AB | I7: Public | J7: Local public authority | K7: PP | L7: Umeå | M7: Västerbottens län | N7: Övre Norrland | O7: 100287 | P7: PO2 | Q7: RSO2.7 | R7: =IF(D7="0. Inget datum inlagt",Tabell1[[#This Row],[Start date]],YEAR(D7)) -> 2023 | S7: Sverige
A8: 58 | B8: AURORA | C8: Regular | D8: 45170 | E8: 46265 | F8: Regenerative nature tourism (REGGAE) | G8: SE799614497601 | H8: Gold of Lappland Ekonomisk förening | I8: Private | J8: Interest groups including NGOs | K8: PP | L8: Norsjö | M8: Västerbottens län | N8: Övre Norrland | O8: 100737 | P8: PO4 | Q8: RSO4.6 | R8: =IF(D8="0. Inget datum inlagt",Tabell1[[#This Row],[Start date]],YEAR(D8)) -> 2023 | S8: Sverige
A9: 136 | B9: AURORA | C9: Regular project | D9: 45597 | E9: 46387 | F9: ICCE | G9: SE799614497601 | H9: Gold of Lappland Ekonomisk förening | I9: Private | J9: Interest groups including NGOs | K9: PP | L9: Norsjö | M9: Västerbottens län | N9: Övre Norrland | O9: 19305 | P9: PO4 | Q9: RSO4.6 | R9: =IF(D9="0. Inget datum inlagt",Tabell1[[#This Row],[Start date]],YEAR(D9)) -> 2024 | S9: Sverige
A10: 129 | B10: AURORA | C10: Regular project | D10: 45505 | E10: 46387 | F10: Torne Valley Dipnet | G10: UPPGIFT SAKNAS | H10: Haparanda Kommun | I10: Public | J10: Local public authority | K10: PP | L10: Haparanda | M10: Norrbottens län | N10: Övre Norrland | O10: 128082 | P10: PO4 | Q10: RSO4.6 | R10: =IF(D10="0. Inget datum inlagt",Tabell1[[#This Row],[Start date]],YEAR(D10)) -> 2024 | S10: Sverige
A11: 43 | B11: AURORA | C11: Small | D11: 44896 | E11: 45260 | F11: Smart ruralities- new solutions for the future of local communities and municipalities (SMART RURAL) | H11: Hela Sverige Ska Leva Norrbotten | I11: Other | J11: Interest groups including NGOs | K11: PP | L11: Boden | M11: Norrbottens län | N11: Övre Norrland | O11: 6370 | P11: ISO | Q11: ISO6.6 | R11: =IF(D11="0. Inget datum inlagt",Tabell1[[#This Row],[Start date]],YEAR(D11)) -> 2022 | S11: Sverige
A12: 44 | B12: AURORA | C12: Small | D12: 44896 | E12: 45260 | F12: Smart ruralities- new solutions for the future of local communities and municipalities (SMART RURAL) | H12: Hela Sverige Ska Leva Västerbotten | I12: Other | J12: Interest groups including NGOs | K12: PP | L12: Norsjö | M12: Västerbottens län | N12: Övre Norrland | O12: 6370 | P12: ISO | Q12: ISO6.6 | R12: =IF(D12="0. Inget datum inlagt",Tabell1[[#This Row],[Start date]],YEAR(D12)) -> 2022 | S12: Sverige
A13: 20 | B13: AURORA | C13: Regular | D13: 44927 | E13: 46022 | F13: ClimateFood: Climate-Smart Food via Cross-Border Cooperation - With Businesses, for the Businesses! | G13: SE262000025301 | H13: Hushållningssällskapet I Norrbotten-Västerbotten | I13: Public | J13: Business support organisation | K13: PP | L13: Luleå | M13: Norrbottens län | N13: Övre Norrland | O13: 69135 | P13: PO1 | Q13: RSO1.3 | R13: =IF(D13="0. Inget datum inlagt",Tabell1[[#This Row],[Start date]],YEAR(D13)) -> 2023 | S13: Sverige
A14: 140 | B14: AURORA | C14: Regular project | D14: 45536 | E14: 46630 | F14: REWATER | G14: SE262000025301 | H14: Hushållningssällskapet I Norrbotten-Västerbotten | I14: Public | J14: Business support organisation | K14: PP | L14: Piteå | M14: Norrbottens län | N14: Övre Norrland | O14: 124331 | P14: PO2 | Q14: RSO2.4 | R14: =IF(D14="0. Inget datum inlagt",Tabell1[[#This Row],[Start date]],YEAR(D14)) -> 2024 | S14: Sverige
A15: 112 | B15: AURORA | C15: Small | D15: 45413 | E15: 45657 | F15: Innovation in urban planning | G15: SE212000240301 | H15: Härnösands kommun | I15: Public | J15: Local public authority | K15: LP | L15: Härnösand | M15: Västernorrlands län | N15: Mellersta Norrland | O15: 12999 | P15: ISO | Q15: ISO6.6 | R15: =IF(D15="0. Inget datum inlagt",Tabell1[[#This Row],[Start date]],YEAR(D15)) -> 2024 | S15: Sverige
A16: 111 | B16: AURORA | C16: Small | D16: 45383 | E16: 45657 | F16: Power line monitoring for increased resilience | G16: SE559316141601 | H16: I.B. Vogt Ab | I16: Private | J16: Small or medium-sized enterprise (SME) | K16: PP | L16: Stockholm | M16: Stockholms län | N16: Stockholm | O16: 1365 | P16: PO2 | Q16: RSO2.4 | R16: =IF(D16="0. Inget datum inlagt",Tabell1[[#This Row],[Start date]],YEAR(D16)) -> 2024 | S16: Sverige
A17: 55 | B17: AURORA | C17: Regular | D17: 45170 | E17: 46265 | F17: Food education for the future | G17: SE212000269201 | H17: Kalix Kommun | I17: Public | J17: Local public authority | K17: PP | L17: Kalix | M17: Norrbottens län | N17: Övre Norrland | O17: 32486 | P17: PO2 | Q17: RSO2.4 | R17: =IF(D17="0. Inget datum inlagt",Tabell1[[#This Row],[Start date]],YEAR(D17)) -> 2023 | S17: Sverige
A18: 37 | B18: AURORA | C18: Regular | D18: 44927 | E18: 46022 | F18: Bothnia Green Energy | G18: SE556789410901 | H18: Kompetensspridning i Umeå AB | I18: Private | J18: Education and research institution | K18: PP | L18: Umeå | M18: Västerbottens län | N18: Övre Norrland | O18: 21664 | P18: PO1 | Q18: RSO1.3 | R18: =IF(D18="0. Inget datum inlagt",Tabell1[[#This Row],[Start date]],YEAR(D18)) -> 2023 | S18: Sverige
A19: 134 | B19: AURORA | C19: Regular project | D19: 45597 | E19: 46387 | F19: ICCE | G19: SE222000320201 | H19: Konstmuseet I Norr | I19: Public | J19: Local public authority | K19: PP | L19: Kiruna | M19: Norrbottens län | N19: Övre Norrland | O19: 89846 | P19: PO4 | Q19: RSO4.6 | R19: =IF(D19="0. Inget datum inlagt",Tabell1[[#This Row],[Start date]],YEAR(D19)) -> 2024 | S19: Sverige
A20: 101 | B20: AURORA | C20: Regular | D20: 45323 | E20: 46418 | F20: Nordic Music Creators | G20: SE8954012640 | H20: Kultur Akademin, Ideell Förening | I20: Private | J20: NGO | K20: PP | L20: Storuman | M20: Västerbottens län | N20: Övre Norrland | O20: 83645 | P20: PO4 | Q20: RSO4.6 | R20: =IF(D20="0. Inget datum inlagt",Tabell1[[#This Row],[Start date]],YEAR(D20)) -> 2024 | S20: Sverige
A21: 5 | B21: AURORA | C21: Regular | D21: 44958 | E21: 46022 | F21: ICH North - passing on our musical heritage | G21: SE8024351689 | H21: Kulturens Bildningsverksamhet (Kbv) | I21: Private | J21: NGO | K21: PP | L21: Sundbyberg | M21: Stockholms län | N21: Stockholm | O21: 10000 | P21: PO4 | Q21: RSO4.6 | R21: =IF(D21="0. Inget datum inlagt",Tabell1[[#This Row],[Start date]],YEAR(D21)) -> 2023 | S21: Sverige
A22: 65 | B22: AURORA | C22: Regular | D22: 45200 | E22: 46295 | F22: Best practices for sustainable stabilisation and reuse of sulfidic soils with minimised environmental impact (MinImpact) | G22: SE202100627101 | H22: Linnéuniversitetet | I22: Public | J22: Higher education and research institution | K22: PP | L22: Kalmar | M22: Kalmar län | N22: Småland med öarna | O22: 163723 | P22: PO2 | Q22: RSO2.7 | R22: =IF(D22="0. Inget datum inlagt",Tabell1[[#This Row],[Start date]],YEAR(D22)) -> 2023 | S22: Sverige
A23: 11 | B23: AURORA | C23: Regular | D23: 44896 | E23: 45991 | F23: SCABEAC - Sustainable Construction and Build Environment in Arctic Climate | G23: SE556604512501 | H23: LTU Business AB | I23: Public | J23: Higher education and research institution | K23: LP | L23: Luleå | M23: Norrbottens län | N23: Övre Norrland | O23: 191550 | P23: PO1 | Q23: RSO1.3 | R23: =IF(D23="0. Inget datum inlagt",Tabell1[[#This Row],[Start date]],YEAR(D23)) -> 2022 | S23: Sverige
A24: 113 | B24: AURORA | C24: Small | D24: 45383 | E24: 45565 | F24: Tiny homes preparatory project | G24: SE556604512501 | H24: LTU Business AB | I24: Public | J24: Business support organisation | K24: PP | L24: Luleå | M24: Norrbottens län | N24: Övre Norrland | O24: 12740 | P24: PO1 | Q24: RSO1.1 | R24: =IF(D24="0. Inget datum inlagt",Tabell1[[#This Row],[Start date]],YEAR(D24)) -> 2024 | S24: Sverige
... A70: 96 | B70: AURORA | C70: Regular | D70: 45231 | E70: 46326 | F70: Felles Fjellrev - Together for the arctic fox | G70: SE202100246001 | H70: Länsstyrelsen Västerbotten | I70: Public | J70: National public authority | K70: PP | L70: Umeå | M70: Västerbottens län | N70: Övre Norrland | O70: 217184 | P70: PO2 | Q70: RSO2.7 | R70: =IF(D70="0. Inget datum inlagt",Tabell1[[#This Row],[Start date]],YEAR(D70)) -> 2023 | S70: Sverige
A71: 83 | B71: AURORA | C71: Small | D71: 45139 | E71: 45322 | F71: Pre-study for capasity building a network of cooperation in the field of Finno Ugric cultures, languages and sustainable tourism in the North | H71: Meänsuomen Föreeninki - Byfinska Föreningen | I71: Other | J71: Other | K71: PP | L71: Kiruna | M71: Norrbottens län | N71: Övre Norrland | O71: 9100 | P71: ISO | Q71: ISO6.6 | R71: =IF(D71="0. Inget datum inlagt",Tabell1[[#This Row],[Start date]],YEAR(D71)) -> 2023 | S71: Sverige
A72: 30 | B72: AURORA | C72: Small | D72: 44866 | E72: 45138 | F72: Nordic Battery Belt - Feasibility study | G72: SE8954008762 | H72: Midtskandia | I72: Other | J72: Other | K72: PP | L72: Storuman | M72: Västerbottens län | N72: Övre Norrland | O72: 1740 | P72: ISO | Q72: ISO6.6 | R72: =IF(D72="0. Inget datum inlagt",Tabell1[[#This Row],[Start date]],YEAR(D72)) -> 2022 | S72: Sverige
A73: 57 | B73: AURORA | C73: Regular | D73: 45170 | E73: 46265 | F73: Regenerative nature tourism (REGGAE) | G73: SE202100452401 | H73: Mittuniversitetet | I73: Public | J73: Higher education and research institution | K73: PP | L73: Östersund | M73: Jämtlands län | N73: Mellersta Norrland | O73: 181490 | P73: PO4 | Q73: RSO4.6 | R73: =IF(D73="0. Inget datum inlagt",Tabell1[[#This Row],[Start date]],YEAR(D73)) -> 2023 | S73: Sverige
A74: 74 | B74: AURORA | C74: Regular | D74: 45170 | E74: 46265 | F74: RemotE seNsing and data fuSion integration for IndUstrial logistics in Rural ArEas with 6G (ENSURE-6G) | G74: SE202100452401 | H74: Mittuniversitetet | I74: Public | J74: Higher education and research institution | K74: PP | L74: Sundsvall | M74: Västernorrlands län | N74: Mellersta Norrland | O74: 303713 | P74: PO1 | Q74: RSO1.1 | R74: =IF(D74="0. Inget datum inlagt",Tabell1[[#This Row],[Start date]],YEAR(D74)) -> 2023 | S74: Sverige
A75: 82 | B75: AURORA | C75: Small | D75: 45152 | E75: 45354 | F75: Air herding: Large scale implementation of drones in reindeer husbandry, a user perspective [AIRHERD] | G75: SE202100452401 | H75: Mittuniversitetet | I75: Public | J75: Higher education and research institution | K75: LP | L75: Sundsvall | M75: Västernorrlands län | N75: Mellersta Norrland | O75: 12985 | P75: ISO | Q75: ISO6.6 | R75: =IF(D75="0. Inget datum inlagt",Tabell1[[#This Row],[Start date]],YEAR(D75)) -> 2023 | S75: Sverige
A76: 121 | B76: AURORA | C76: Regular project | D76: 45505 | E76: 46599 | F76: IMMERSE | G76: SE202100452401 | H76: Mittuniversitetet | I76: Public | J76: Higher education and research institution | K76: LP | L76: Sundsvall | M76: Västernorrlands län | N76: Mellersta Norrland | O76: 426816 | P76: PO1 | Q76: RSO1.1 | R76: =IF(D76="0. Inget datum inlagt",Tabell1[[#This Row],[Start date]],YEAR(D76)) -> 2024 | S76: Sverige
A77: 142 | B77: AURORA | C77: Regular project | D77: 45536 | E77: 46630 | F77: Flexible and Sustainable Solid-State Batteries for Cold-Weather Electronic Applications | G77: SE202100452401 | H77: Mittuniversitetet | I77: Public | J77: Higher education and research institution | K77: PP | L77: Östersund | M77: Jämtlands län | N77: Mellersta Norrland | O77: 155993 | P77: PO1 | Q77: RSO1.1 | R77: =IF(D77="0. Inget datum inlagt",Tabell1[[#This Row],[Start date]],YEAR(D77)) -> 2024 | S77: Sverige
A78: 102 | B78: AURORA | C78: Regular | D78: 45536 | E78: 46630 | F78: RE-ARCHTIVE NORTH. Innovative strategies for the re-use and re-activation of the architectural heritage in Northern peripheral areas | H78: Moskoselcreativepark | I78: Private | J78: NGO | K78: PP | L78: Arvidsjaur | M78: Norrbottens län | N78: Övre Norrland | O78: 50261 | P78: PO4 | Q78: RSO4.6 | R78: =IF(D78="0. Inget datum inlagt",Tabell1[[#This Row],[Start date]],YEAR(D78)) -> 2024 | S78: Sverige
A79: 63 | B79: AURORA | C79: Regular | D79: 45170 | E79: 46265 | F79: ReCap ASáP: Regaining capacity in a changing Sápmi | H79: Nordiska Samerådet | I79: Public | J79: National public authority | K79: LP | L79: Jokkmokk | M79: Norrbottens län | N79: Övre Norrland | O79: 568589 | P79: ISO | Q79: ISO6.6 | R79: =IF(D79="0. Inget datum inlagt",Tabell1[[#This Row],[Start date]],YEAR(D79)) -> 2023 | S79: Sverige
A80: 67 | B80: AURORA | C80: Regular | D80: 45170 | E80: 46265 | F80: Arctic Music Circles | G80: SE556529619001 | H80: NorrlandsOperan Aktiebolag | I80: Private | J80: Local public authority | K80: PP | L80: Umeå | M80: Västerbottens län | N80: Övre Norrland | O80: 200850 | P80: PO4 | Q80: RSO4.6 | R80: =IF(D80="0. Inget datum inlagt",Tabell1[[#This Row],[Start date]],YEAR(D80)) -> 2023 | S80: Sverige
A81: 116 | B81: AURORA | C81: Small | D81: 45413 | E81: 45657 | F81: Exploring Cross-Border Collaboration for Sustainable Entrepreneurship | G81: SE556099937601 | H81: Piteå Science Park Ab | I81: Public | J81: Business support organisation | K81: PP | L81: Piteå | M81: Norrbottens län | N81: Övre Norrland | O81: 5200 | P81: PO1 | Q81: RSO1.3 | R81: =IF(D81="0. Inget datum inlagt",Tabell1[[#This Row],[Start date]],YEAR(D81)) -> 2024 | S81: Sverige
A82: 68 | B82: AURORA | C82: Regular | D82: 45170 | E82: 46265 | F82: Arctic Music Circles | G82: SE232100023001 | H82: Region Norrbotten | I82: Public | J82: Regional public authority | K82: LP | L82: Luleå | M82: Norrbottens län | N82: Övre Norrland | O82: 313300 | P82: PO4 | Q82: RSO4.6 | R82: =IF(D82="0. Inget datum inlagt",Tabell1[[#This Row],[Start date]],YEAR(D82)) -> 2023 | S82: Sverige
A83: 130 | B83: AURORA | C83: Regular project | D83: 45505 | E83: 46387 | F83: Torne Valley Dipnet | G83: SE232100023001 | H83: Region Norrbotten | I83: Public | J83: Regional public authority | K83: PP | L83: Luleå | M83: Norrbottens län | N83: Övre Norrland | O83: 47175 | P83: PO4 | Q83: RSO4.6 | R83: =IF(D83="0. Inget datum inlagt",Tabell1[[#This Row],[Start date]],YEAR(D83)) -> 2024 | S83: Sverige
A84: 109 | B84: AURORA | C84: Small | D84: 45383 | E84: 45657 | F84: Power line monitoring for increased resilience | G84: SE232100022201 | H84: Region Västerbotten | I84: Public | J84: Regional public authority | K84: PP | L84: Umeå | M84: Västerbottens län | N84: Övre Norrland | O84: 1638 | P84: PO2 | Q84: RSO2.4 | R84: =IF(D84="0. Inget datum inlagt",Tabell1[[#This Row],[Start date]],YEAR(D84)) -> 2024 | S84: Sverige
A85: 115 | B85: AURORA | C85: Small | D85: 45383 | E85: 45657 | F85: Kvarken Film Network | G85: SE232100022201 | H85: Region Västerbotten | I85: Public | J85: Regional public authority | K85: PP | L85: Umeå | M85: Västerbottens län | N85: Övre Norrland | O85: 13000 | P85: PO4 | Q85: RSO4.6 | R85: =IF(D85="0. Inget datum inlagt",Tabell1[[#This Row],[Start date]],YEAR(D85)) -> 2024 | S85: Sverige
...

Sheet ProjektPerLän
A1: Land | B1: NUTS 3 | C1: Antal av Project name
A2: Sverige | B2: Dalarnas län | C2: 2
A3: Sverige | B3: Hallands län | C3: 5
A4: Sverige | B4: Jämtlands län | C4: 6
A5: Sverige | B5: Kronobergs län | C5: 1
A6: Sverige | B6: Norrbottens län | C6: 34
A7: Sverige | B7: Skåne län | C7: 41
A8: Sverige | B8: Stockholms län | C8: 12
A9: Sverige | B9: Värmlands län | C9: 7
A10: Sverige | B10: Västerbottens län | C10: 24
A11: Sverige | B11: Västernorrlands län | C11: 11
A12: Sverige | B12: Västra Götalands län | C12: 28

Sheet Projektpartnerstyp
A1: Radetiketter
A2: LP
A3: PP
A4: Totalsumma

Sheet Budget
A3: Radetiketter | B3: Summa av ERDF per partner
A4: 2022 | B4: 7452791.5
A5: 2023 | B5: 20270862
A6: 2024 | B6: 8620403.9
A7: 2025 | B7: 6469148.3
A8: 2026 | B8: 514286
A9: Totalsumma | B9: 43327492
D16: Summa av ERDF per partner
D17: =GETPIVOTDATA("Summa av ERDF per partner",$A$3) -> 43327492

Sheet AntalProjekt
A1: Radetiketter | B1: Antal projekt
A2: Baltic Sea Region | B2: 13
A3: Interreg europe | B3: 2
A4: AURORA | B4: 53
A5: Sverige-Norge | B5: 21
A6: Öresund-Kattegat-Skagerrak | B6: 45
A7: Northern Periphery and Arctic | B7: 12 | D7: Total antal projektpartners
A8: Interreg North Sea | B8: 25 | D8: =GETPIVOTDATA("Project name",$A$1) -> 171
A9: Totalsumma | B9: 171

Sheet UnikaProjekt
A1: Radetiketter
A2: ACE | D2: Antal unika projekt
A3: Arts on Prescription | D3: =CONCATENATE(D2,":",CHAR(10),(COUNTA(A:A)-2)) -> Antal unika projekt: 93
A4: CR
A5: D4A
A6: Mobile Hospital
A7: PHESIA
A8: RoboDemo
A9: SIRR
A10: StratKIT+
A11: STORM_SAFE
A12: RESIST
A13: DeepTechValleys
A14: HERCULES
A15: GreenBattery
... A95: Totalsumma

Sheet ProjektPerPartnerOrgtyp
A1: Type of partner | B1: Type of organisation | C1: Antal projekt
A2: LP | B2: Business support organisation | C2: 3
A3: LP | B3: Higher education and research institution | C3: 20
A4: LP | B4: Local public authority | C4: 3
A5: LP | B5: Regional public authority | C5: 1
A6: LP | B6: Sectoral agency | C6: 1
A7: LP | B7: Other | C7: 1
A8: PP | B8: Business support organisation | C8: 15
A9: PP | B9: Education and research institution | C9: 2
A10: PP | B10: Higher education and research institution | C10: 64
A11: PP | B11: International governmental organisation | C11: 2
A12: PP | B12: Large enterprise | C12: 2
A13: PP | B13: Local public authority | C13: 16
... A21: PP | B21: Enterprise, except SME | C21: 2

Sheet AntalOrg
A1: Radetiketter | B1: Antal av Organisation name
A2: BioFuel Region BFR AB | B2: 2 | E2: Antal unika organisationer
A3: Chalmers tekniska högskola AB | B3: 1 | E3: =CONCATENATE(E2,":",CHAR(10),(COUNTA(B:B)-2)) -> Antal unika organisationer: 81
A4: Ecoloop AB | B4: 1
A5: Göteborgs Universitet | B5: 4
A6: Höganäs Omsorg (Höganäs Kommun) | B6: 1
A7: Högskolan Väst | B7: 1
A8: Innovation Skåne | B8: 4
A9: Karlstads universitet | B9: 3
A10: Karolinska Universitetssjukhuset | B10: 1
A11: Kungsbacka kommun | B11: 1
A12: Lindholmen Science Park AB | B12: 3
A13: Luleå Tekniska Universitet | B13: 29
A14: Lunds Kommun | B14: 1
A15: Lunds Universitet | B15: 9
... A83: Totalsumma | B83: 171

Sheet SpecifiktMål
A1: Radetiketter | B1: Summa av ERDF per partner
A2: RSO1.1 | B2: 43327492
A3: Totalsumma | B3: 43327492

Sheet Program
A1: Radetiketter
A2: Baltic Sea Region
A3: Interreg europe
A4: AURORA
A5: Sverige-Norge
A6: Öresund-Kattegat-Skagerrak
A7: Northern Periphery and Arctic
A8: Interreg North Sea
A9: Totalsumma

Sheet Stad

Sheet Projekt
A1: Projekt | B1: (Alla)

Sheet Organisation
A1: Organisation | B1: (Alla)

Sheet Top3Projekt
A1: Tre största projekten | B1: Summa Partnerbudget
A2: HALRIC - Hanseatic Life Science Research Infrastructure Consortium for triple-helix innovation | B2: 2096250
A3: SIRR | B3: 2077318
A4: DigiH4A | B4: 1631524
A5: Totalsumma | B5: 5805092

Sheet Top3Org
A1: Tre största organisationerna | B1: Summa Partnerbudget
A2: Luleå Tekniska Universitet | B2: 6775308.6
A3: Lunds Universitet | B3: 3656247
A4: Mittuniversitetet | B4: 2933275
A5: Totalsumma | B5: 13364831

Sheet Tidsintervall
A1: Project name | B1: Start date | C1: End date | D1: Datum_formel
A2: ACE | B2: 44927 | C2: 46203 | D2: 2023
A3: Arts on Prescription | B3: 44828 | C3: 46112 | D3: 2022
A4: CR | B4: 44927 | C4: 46387 | D4: 2023
A5: D4A | B5: 44824 | C5: 46022 | D5: 2022
A6: Mobile Hospital | B6: 45037 | C6: 45961 | D6: 2023
A7: PHESIA | B7: 45078 | C7: 45260 | D7: 2023
A8: RoboDemo | B8: 44896 | C8: 45991 | D8: 2022
A9: SIRR | B9: 44835 | C9: 46660 | D9: 2022
A10: StratKIT+ | B10: 44728 | C10: 45473 | D10: 2022 | F10: Start date | G10: End date
A11: STORM_SAFE | B11: 45292 | C11: 46752 | D11: 2024 | F11: =MIN(B:B) -> 44728 | G11: =MAX(C:C) -> 47118
A12: RESIST | B12: 45098 | C12: 46418 | D12: 2023
A13: DeepTechValleys | B13: 45383 | C13: 46934 | D13: 2024 | F13: 44197
A14: HERCULES | B14: 45383 | C14: 46934 | D14: 2024
A15: GreenBattery | B15: 44927 | C15: 46022 | D15: 2023
A16: SUSEN - Knowledge and networking platform for sustainable electronics based on northern bioresources - Sustainable electronics from Northern bioresources - Biotronics | B16: 44927 | C16: 46022 | D16: 2023
A17: Arctic 6G | B17: 44896 | C17: 45991 | D17: 2022
A18: HE4T - Harvesting Energy for Data Acquisition and Transfer | B18: 44927 | C18: 46022 | D18: 2023
A19: Summation - (Sustainable Autonomous Systems and Solutions) | B19: 44927 | C19: 46022 | D19: 2023
A20: Eco-friendly and sustainable method for recycling of spent lithium-ion batteries (EcoLIB) | B20: 44927 | C20: 46022 | D20: 2023
A21: Sustainable Hydrogen - Potential for Bothnia Gulf Cluster | B21: 44927 | C21: 46022 | D21: 2023
A22: Boost Nordic Biogas | B22: 44927 | C22: 46022 | D22: 2023
A23: Sustainable Autonomous Material Handling (SAMHand) | B23: 44927 | C23: 46022 | D23: 2023
A24: OFFwind - Offshore Wind Turbine Farms | B24: 44866 | C24: 45961 | D24: 2022
A25: Implementation of DeD AM in future manufacturing | B25: 44927 | C25: 46022 | D25: 2023
... A95: BATTSi | B95: 45717 | C95: 46812 | D95: 2025

Sheet PublicPrivateOrg
A1: Radetiketter | B1: Antal av Organisation name
A2: Private | B2: 20
A3: Public | B3: 148
A4: Other | B4: 3
A5: Totalsumma | B5: 171

Sheet UnikaProjPerProg
A1: Programme | B1: Project name | F1: {=_xlfn.UNIQUE(_xlfn._xlws.FILTER(A:A,A:A<>""))} -> Programme
A2: Baltic Sea Region | B2: Arts on Prescription | F2: Baltic Sea Region | G2: =IF(F2="","",(COUNTIFS(A:A,F2))) -> 9
A3: Baltic Sea Region | B3: Mobile Hospital | F3: Interreg europe | G3: =IF(F3="","",(COUNTIFS(A:A,F3))) -> 2
A4: Baltic Sea Region | B4: StratKIT+ | F4: AURORA | G4: =IF(F4="","",(COUNTIFS(A:A,F4))) -> 38
A5: Baltic Sea Region | B5: RESIST | F5: Sverige-Norge | G5: =IF(F5="","",(COUNTIFS(A:A,F5))) -> 9
A6: Baltic Sea Region | B6: SmartAging | F6: Öresund-Kattegat-Skagerrak | G6: =IF(F6="","",(COUNTIFS(A:A,F6))) -> 16
A7: Baltic Sea Region | B7: CliNeDest | F7: Northern Periphery and Arctic | G7: =IF(F7="","",(COUNTIFS(A:A,F7))) -> 7
A8: Baltic Sea Region | B8: REDIRECT | F8: Interreg North Sea | G8: =IF(F8="","",(COUNTIFS(A:A,F8))) -> 12
A9: Baltic Sea Region | B9: CREWS | G9: =IF(F9="","",(COUNTIFS(A:A,F9)))
A10: Baltic Sea Region | B10: DIVERSE_GENE_WATCH | G10: =IF(F10="","",(COUNTIFS(A:A,F10)))
A11: Interreg europe | B11: DeepTechValleys | G11: =IF(F11="","",(COUNTIFS(A:A,F11)))
A12: Interreg europe | B12: HERCULES
A13: AURORA | B13: GreenBattery
A14: AURORA | B14: SUSEN - Knowledge and networking platform for sustainable electronics based on northern bioresources - Sustainable electronics from Northern bioresources - Biotronics
A15: AURORA | B15: Arctic 6G
A16: AURORA | B16: HE4T - Harvesting Energy for Data Acquisition and Transfer
A17: AURORA | B17: Summation - (Sustainable Autonomous Systems and Solutions)
A18: AURORA | B18: Eco-friendly and sustainable method for recycling of spent lithium-ion batteries (EcoLIB)
A19: AURORA | B19: Sustainable Hydrogen - Potential for Bothnia Gulf Cluster
A20: AURORA | B20: Boost Nordic Biogas
A21: AURORA | B21: Sustainable Autonomous Material Handling (SAMHand)
A22: AURORA | B22: OFFwind - Offshore Wind Turbine Farms
A23: AURORA | B23: Implementation of DeD AM in future manufacturing
... A94: Interreg North Sea | B94: H2ignite
